Workbook

Sheet Main
A1: Какое озеро является самым глубоким в мире? | B1: Байкал | C1: Каспийское | D1: Виктория | E1: Танганьика | F1: 1 | G1: Озеро Байкал — самое глубокое в мире, его максимальная глубина составляет около 1642 метров.
A2: Какой химический элемент является основой органических соединений? | B2: Кремний | C2: Углерод | D2: Кислород | E2: Азот | F2: 2 | G2: Углерод образует основу органических соединений благодаря способности создавать длинные цепочки атомов.
A3: Какой город был столицей Древнего Египта в эпоху Нового царства? | B3: Мемфис | C3: Фивы | D3: Александрия | E3: Гиза | F3: 2 | G3: Фивы были столицей Египта в период Нового царства примерно с XVI по XI век до н. э.
A4: Какой отдел нервной системы отвечает за непроизвольные реакции? | B4: Соматическая | C4: Центральная | D4: Вегетативная | E4: Периферическая | F4: 3 | G4: Вегетативная нервная система регулирует непроизвольные процессы, такие как сердцебиение, дыхание и работа внутренних органов.
A5: Какая река считается самой длинной в Азии? | B5: Ганг | C5: Хуанхэ | D5: Янцзы | E5: Меконг | F5: 3 | G5: Длина реки Янцзы составляет около 6300 километров, что делает её самой длинной в Азии.
A6: Какое море считается самым глубоким в мире? | B6: Чёрное | C6: Средиземное | D6: Красное | E6: Карибское | F6: 1 | G6: Чёрное море имеет максимальную глубину около 2210 метров, что делает его самым глубоким морем Мирового океана.
A7: Какой материк имеет наибольшую среднюю высоту над уровнем моря? | B7: Африка | C7: Азия | D7: Южная Америка | E7: Антарктида | F7: 4 | G7: Средняя высота Антарктиды превышает 2000 метров из-за мощного ледникового покрова.
A8: Какой океан омывает восточное побережье Южной Америки? | B8: Тихий | C8: Индийский | D8: Атлантический | E8: Южный | F8: 3 | G8: Восточное побережье Южной Америки омывается Атлантическим океаном.
A9: Кто написал роман «1984»? | B9: Олдос Хаксли | C9: Джордж Оруэлл | D9: Рэй Брэдбери | E9: Франц Кафка | F9: 2 | G9: Антиутопический роман «1984» был опубликован Джорджем Оруэллом в 1949 году.
A10: Какой орган человека отвечает за детоксикацию крови? | B10: Почки | C10: Печень | D10: Сердце | E10: Лёгкие | F10: 2 | G10: Печень обезвреживает токсичные вещества и продукты обмена веществ.
A11: Какая страна первой приняла конституцию в современном виде? | B11: Франция | C11: Англия | D11: США | E11: Германия | F11: 3 | G11: Конституция США была принята в 1787 году и действует с поправками до сих пор.
A12: Как называется самая высокая точка Африки? | B12: Атлас | C12: Килиманджаро | D12: Драконовы горы | E12: Рувензори | F12: 2 | G12: Гора Килиманджаро имеет высоту около 5895 метров над уровнем моря.
... A26: Какой философ был учителем Александра Македонского? | B26: Платон | C26: Аристотель | D26: Сократ | E26: Эпикур | F26: 2 | G26: Аристотель обучал Александра Македонского философии и наукам в IV веке до н. э.
A27: В каком году человек впервые высадился на Луну? | B27: 1965 | C27: 1969 | D27: 1972 | E27: 1980 | F27: 2 | G27: Первая высадка человека на Луну состоялась в 1969 году в ходе миссии «Аполлон-11», когда Нил Армстронг ступил на поверхность спутника Земли.
A28: Какой химический элемент является самым распространённым во Вселенной? | B28: Кислород | C28: Водород | D28: Гелий | E28: Углерод | F28: 2 | G28: Водород составляет около 75 % всей видимой материи Вселенной и является основным компонентом звёзд.
A29: Какой материк полностью расположен в Южном полушарии? | B29: Южная Америка | C29: Африка | D29: Австралия | E29: Евразия | F29: 3 | G29: Австралия целиком находится в Южном полушарии и омывается Индийским и Тихим океанами.
A30: Какой прибор используется для измерения силы землетрясений? | B30: Термометр | C30: Сейсмограф | D30: Барометр | E30: Анемометр | F30: 2 | G30: Сейсмограф регистрирует колебания земной коры и позволяет определить силу и характеристики землетрясений.
A31: Какой материк является самым сухим на Земле? | B31: Африка | C31: Австралия | D31: Антарктида | E31: Южная Америка | F31: 3 | G31: Антарктида считается самым сухим материком, так как в её внутренних районах выпадает менее 50 мм осадков в год.
A32: Какое государство считается преемником Византийской империи? | B32: Болгария | C32: Османская империя | D32: Священная Римская империя | E32: Римская республика | F32: 2 | G32: После падения Константинополя в 1453 году Византийская империя была завоёвана Османской империей, которая унаследовала её территории.
A33: Какой химический элемент имеет атомный номер 1? | B33: Гелий | C33: Водород | D33: Литий | E33: Кислород | F33: 2 | G33: Водород — первый элемент таблицы Менделеева, его атом состоит из одного протона.
A34: Какой пролив соединяет Чёрное море с Мраморным? | B34: Дарданеллы | C34: Босфор | D34: Гибралтар | E34: Ла-Манш | F34: 2 | G34: Пролив Босфор соединяет Чёрное и Мраморное моря и проходит через территорию Стамбула.
A35: Какой орган человека отвечает за выработку инсулина? | B35: Печень | C35: Поджелудочная железа | D35: Желудок | E35: Селезёнка | F35: 2 | G35: Поджелудочная железа вырабатывает инсулин — гормон, регулирующий уровень сахара в крови.
A36: Какое государство имеет наибольшее население в мире? | B36: Индия | C36: США | D36: Китай | E36: Индонезия | F36: 1 | G36: Индия стала самой населённой страной мира в 2023 году, превысив население Китая.
A37: Кто был первым императором Римской империи? | B37: Юлий Цезарь | C37: Октавиан Август | D37: Нерон | E37: Калигула | F37: 2 | G37: Октавиан Август стал первым императором Рима в 27 году до н. э., положив начало Римской империи.
A38: Какой материк является самым маленьким по площади? | B38: Европа | C38: Антарктида | D38: Австралия | E38: Южная Америка | F38: 3 | G38: Австралия — самый маленький материк, её площадь составляет около 7,7 млн км².
A39: В каком веке произошло крещение Руси? | B39: IX | C39: X | D39: XI | E39: XII | F39: 2 | G39: Крещение Руси состоялось в 988 году при князе Владимире, что относится к X веку.
... A57: Как называется эпоха, последовавшая за Средневековьем? | B57: Античность | C57: Новое время | D57: Просвещение | E57: Возрождение | F57: 2 | G57: Новое время началось примерно в XV веке и связано с развитием науки, географическими открытиями и изменениями в обществе.

Sheet export
A1: Вопрос | B1: Вариант1 | C1: Вариант2 | D1: Вариант3 | E1: Вариант4 | F1: Индекс | G1: Пояснение
A2: =Main!A2 -> Какой химический элемент является основой органических соединений? | B2: =Main!B2 -> Кремний | C2: =Main!C2 -> Углерод | D2: =Main!D2 -> Кислород | E2: =Main!E2 -> Азот | F2: =Main!F2 -> 2 | G2: =Main!G2 -> Углерод образует основу органических соединений благодаря способности создавать длинные цепочки атомов.
A3: =Main!A3 -> Какой город был столицей Древнего Египта в эпоху Нового царства? | B3: =Main!B3 -> Мемфис | C3: =Main!C3 -> Фивы | D3: =Main!D3 -> Александрия | E3: =Main!E3 -> Гиза | F3: =Main!F3 -> 2 | G3: =Main!G3 -> Фивы были столицей Египта в период Нового царства примерно с XVI по XI век до н. э.
A4: =Main!A4 -> Какой отдел нервной системы отвечает за непроизвольные реакции? | B4: =Main!B4 -> Соматическая | C4: =Main!C4 -> Центральная | D4: =Main!D4 -> Вегетативная | E4: =Main!E4 -> Периферическая | F4: =Main!F4 -> 3 | G4: =Main!G4 -> Вегетативная нервная система регулирует непроизвольные процессы, такие как сердцебиение, дыхание и работа внутренних органов.
A5: =Main!A5 -> Какая река считается самой длинной в Азии? | B5: =Main!B5 -> Ганг | C5: =Main!C5 -> Хуанхэ | D5: =Main!D5 -> Янцзы | E5: =Main!E5 -> Меконг | F5: =Main!F5 -> 3 | G5: =Main!G5 -> Длина реки Янцзы составляет около 6300 километров, что делает её самой длинной в Азии.
A6: =Main!A6 -> Какое море считается самым глубоким в мире? | B6: =Main!B6 -> Чёрное | C6: =Main!C6 -> Средиземное | D6: =Main!D6 -> Красное | E6: =Main!E6 -> Карибское | F6: =Main!F6 -> 1 | G6: =Main!G6 -> Чёрное море имеет максимальную глубину около 2210 метров, что делает его самым глубоким морем Мирового океана.
A7: =Main!A7 -> Какой материк имеет наибольшую среднюю высоту над уровнем моря? | B7: =Main!B7 -> Африка | C7: =Main!C7 -> Азия | D7: =Main!D7 -> Южная Америка | E7: =Main!E7 -> Антарктида | F7: =Main!F7 -> 4 | G7: =Main!G7 -> Средняя высота Антарктиды превышает 2000 метров из-за мощного ледникового покрова.
A8: =Main!#REF! -> #REF! | B8: =Main!#REF! -> #REF! | C8: =Main!#REF! -> #REF! | D8: =Main!#REF! -> #REF! | E8: =Main!#REF! -> #REF! | F8: =Main!#REF! -> #REF! | G8: =Main!#REF! -> #REF!
A9: =Main!A8 -> Какой океан омывает восточное побережье Южной Америки? | B9: =Main!B8 -> Тихий | C9: =Main!C8 -> Индийский | D9: =Main!D8 -> Атлантический | E9: =Main!E8 -> Южный | F9: =Main!F8 -> 3 | G9: =Main!G8 -> Восточное побережье Южной Америки омывается Атлантическим океаном.
A10: =Main!A9 -> Кто написал роман «1984»? | B10: =Main!B9 -> Олдос Хаксли | C10: =Main!C9 -> Джордж Оруэлл | D10: =Main!D9 -> Рэй Брэдбери | E10: =Main!E9 -> Франц Кафка | F10: =Main!F9 -> 2 | G10: =Main!G9 -> Антиутопический роман «1984» был опубликован Джорджем Оруэллом в 1949 году.
A11: =Main!#REF! -> #REF! | B11: =Main!#REF! -> #REF! | C11: =Main!#REF! -> #REF! | D11: =Main!#REF! -> #REF! | E11: =Main!#REF! -> #REF! | F11: =Main!#REF! -> #REF! | G11: =Main!#REF! -> #REF!
A12: =Main!A10 -> Какой орган человека отвечает за детоксикацию крови? | B12: =Main!B10 -> Почки | C12: =Main!C10 -> Печень | D12: =Main!D10 -> Сердце | E12: =Main!E10 -> Лёгкие | F12: =Main!F10 -> 2 | G12: =Main!G10 -> Печень обезвреживает токсичные вещества и продукты обмена веществ.
A13: =Main!A11 -> Какая страна первой приняла конституцию в современном виде? | B13: =Main!B11 -> Франция | C13: =Main!C11 -> Англия | D13: =Main!D11 -> США | E13: =Main!E11 -> Германия | F13: =Main!F11 -> 3 | G13: =Main!G11 -> Конституция США была принята в 1787 году и действует с поправками до сих пор.
A14: =Main!A12 -> Как называется самая высокая точка Африки? | B14: =Main!B12 -> Атлас | C14: =Main!C12 -> Килиманджаро | D14: =Main!D12 -> Драконовы горы | E14: =Main!E12 -> Рувензори | F14: =Main!F12 -> 2 | G14: =Main!G12 -> Гора Килиманджаро имеет высоту около 5895 метров над уровнем моря.
A15: =Main!A13 -> Какой химический элемент обозначается символом Sn? | B15: =Main!B13 -> Сера | C15: =Main!C13 -> Свинец | D15: =Main!D13 -> Олово | E15: =Main!E13 -> Селен | F15: =Main!F13 -> 3 | G15: =Main!G13 -> Sn — химический символ олова, происходящий от латинского названия Stannum.
A16: =Main!A14 -> Какой материк пересекают оба тропика? | B16: =Main!B14 -> Африка | C16: =Main!C14 -> Южная Америка | D16: =Main!D14 -> Австралия | E16: =Main!E14 -> Евразия | F16: =Main!F14 -> 1 | G16: =Main!G14 -> Африка пересекается тропиком Рака и тропиком Козерога.
A17: =Main!A15 -> Какой писатель является автором романа «Процесс»? | B17: =Main!B15 -> Кафка | C17: =Main!C15 -> Камю | D17: =Main!D15 -> Манн | E17: =Main!E15 -> Гессе | F17: =Main!F15 -> 1 | G17: =Main!G15 -> Роман «Процесс» был написан Францем Кафкой и опубликован посмертно в 1925 году.
A18: =Main!A16 -> Как называется нижний слой атмосферы Земли? | B18: =Main!B16 -> Стратосфера | C18: =Main!C16 -> Мезосфера | D18: =Main!D16 -> Тропосфера | E18: =Main!E16 -> Ионосфера | F18: =Main!F16 -> 3 | G18: =Main!G16 -> Тропосфера простирается до высоты примерно 8–18 километров и содержит большую часть воздуха.
A19: =Main!#REF! -> #REF! | B19: =Main!#REF! -> #REF! | C19: =Main!#REF! -> #REF! | D19: =Main!#REF! -> #REF! | E19: =Main!#REF! -> #REF! | F19: =Main!#REF! -> #REF! | G19: =Main!#REF! -> #REF!
A20: =Main!A17 -> Какой металл используется в ядерной энергетике как топливо? | B20: =Main!B17 -> Плутоний | C20: =Main!C17 -> Железо | D20: =Main!D17 -> Медь | E20: =Main!E17 -> Цинк | F20: =Main!F17 -> 1 | G20: =Main!G17 -> Плутоний применяется как ядерное топливо в реакторах и энергетике.
A21: =Main!A18 -> Какое государство является самым маленьким в мире? | B21: =Main!B18 -> Монако | C21: =Main!C18 -> Ватикан | D21: =Main!D18 -> Сан-Марино | E21: =Main!E18 -> Лихтенштейн | F21: =Main!F18 -> 2 | G21: =Main!G18 -> Площадь Ватикана составляет около 0,44 квадратного километра.
A22: =Main!A19 -> Какой процесс лежит в основе работы тепловых двигателей? | B22: =Main!B19 -> Испарение | C22: =Main!C19 -> Горение | D22: =Main!D19 -> Конденсация | E22: =Main!E19 -> Осмос | F22: =Main!F19 -> 2 | G22: =Main!G19 -> Работа тепловых двигателей основана на выделении энергии при горении топлива.
A23: =Main!A20 -> Какой спутник является крупнейшим в Солнечной системе? | B23: =Main!B20 -> Титан | C23: =Main!C20 -> Ганимед | D23: =Main!D20 -> Луна | E23: =Main!E20 -> Ио | F23: =Main!F20 -> 2 | G23: =Main!G20 -> Ганимед — спутник Юпитера, его диаметр превышает 5200 километров.
A24: =Main!A21 -> Какой элемент необходим для работы щитовидной железы? | B24: =Main!B21 -> Кальций | C24: =Main!C21 -> Йод | D24: =Main!D21 -> Фосфор | E24: =Main!E21 -> Калий | F24: =Main!F21 -> 2 | G24: =Main!G21 -> Йод необходим для синтеза гормонов, регулирующих обмен веществ.
A25: =Main!A22 -> Какой город считается культурной столицей Италии эпохи Возрождения? | B25: =Main!B22 -> Рим | C25: =Main!C22 -> Венеция | D25: =Main!D22 -> Флоренция | E25: =Main!E22 -> Милан | F25: =Main!F22 -> 3 | G25: =Main!G22 -> Флоренция была центром искусства Возрождения в XV–XVI веках.
A26: =Main!A23 -> Какой отдел головного мозга участвует в формировании речи? | B26: =Main!B23 -> Мозжечок | C26: =Main!C23 -> Лобные доли | D26: =Main!D23 -> Теменные доли | E26: =Main!E23 -> Продолговатый мозг | F26: =Main!F23 -> 2 | G26: =Main!G23 -> Лобные доли головного мозга, в частности зона Брока, играют ключевую роль в формировании речи и контроле речевой активности.
A27: =Main!A24 -> Какой океан отделяет Африку от Южной Америки? | B27: =Main!B24 -> Тихий | C27: =Main!C24 -> Индийский | D27: =Main!D24 -> Атлантический | E27: =Main!E24 -> Южный | F27: =Main!F24 -> 3 | G27: =Main!G24 -> Атлантический океан расположен между Африкой и Южной Америкой.
A28: =Main!A25 -> Какой металл является основным компонентом бронзы? | B28: =Main!B25 -> Железо | C28: =Main!C25 -> Олово | D28: =Main!D25 -> Медь | E28: =Main!E25 -> Цинк | F28: =Main!F25 -> 3 | G28: =Main!G25 -> Бронза представляет собой сплав меди с добавлением олова.
A29: =Main!A26 -> Какой философ был учителем Александра Македонского? | B29: =Main!B26 -> Платон | C29: =Main!C26 -> Аристотель | D29: =Main!D26 -> Сократ | E29: =Main!E26 -> Эпикур | F29: =Main!F26 -> 2 | G29: =Main!G26 -> Аристотель обучал Александра Македонского философии и наукам в IV веке до н. э.
A30: =Main!A27 -> В каком году человек впервые высадился на Луну? | B30: =Main!B27 -> 1965 | C30: =Main!C27 -> 1969 | D30: =Main!D27 -> 1972 | E30: =Main!E27 -> 1980 | F30: =Main!F27 -> 2 | G30: =Main!G27 -> Первая высадка человека на Луну состоялась в 1969 году в ходе миссии «Аполлон-11», когда Нил Армстронг ступил на поверхность спутника Земли.
A31: =Main!A28 -> Какой химический элемент является самым распространённым во Вселенной? | B31: =Main!B28 -> Кислород | C31: =Main!C28 -> Водород | D31: =Main!D28 -> Гелий | E31: =Main!E28 -> Углерод | F31: =Main!F28 -> 2 | G31: =Main!G28 -> Водород составляет около 75 % всей видимой материи Вселенной и является основным компонентом звёзд.
... A40: =Main!A37 -> Кто был первым императором Римской империи? | B40: =Main!B37 -> Юлий Цезарь | C40: =Main!C37 -> Октавиан Август | D40: =Main!D37 -> Нерон | E40: =Main!E37 -> Калигула | F40: =Main!F37 -> 2 | G40: =Main!G37 -> Октавиан Август стал первым императором Рима в 27 году до н. э., положив начало Римской империи.
A41: =Main!#REF! -> #REF! | B41: =Main!#REF! -> #REF! | C41: =Main!#REF! -> #REF! | D41: =Main!#REF! -> #REF! | E41: =Main!#REF! -> #REF! | F41: =Main!#REF! -> #REF! | G41: =Main!#REF! -> #REF!
A42: =Main!A38 -> Какой материк является самым маленьким по площади? | B42: =Main!B38 -> Европа | C42: =Main!C38 -> Антарктида | D42: =Main!D38 -> Австралия | E42: =Main!E38 -> Южная Америка | F42: =Main!F38 -> 3 | G42: =Main!G38 -> Австралия — самый маленький материк, её площадь составляет около 7,7 млн км².
A43: =Main!A39 -> В каком веке произошло крещение Руси? | B43: =Main!B39 -> IX | C43: =Main!C39 -> X | D43: =Main!D39 -> XI | E43: =Main!E39 -> XII | F43: =Main!F39 -> 2 | G43: =Main!G39 -> Крещение Руси состоялось в 988 году при князе Владимире, что относится к X веку.
A44: =Main!A40 -> Какой металл является основным компонентом стали? | B44: =Main!B40 -> Алюминий | C44: =Main!C40 -> Медь | D44: =Main!D40 -> Железо | E44: =Main!E40 -> Никель | F44: =Main!F40 -> 3 | G44: =Main!G40 -> Сталь представляет собой сплав на основе железа с добавлением углерода.
A45: =Main!#REF! -> #REF! | B45: =Main!#REF! -> #REF! | C45: =Main!#REF! -> #REF! | D45: =Main!#REF! -> #REF! | E45: =Main!#REF! -> #REF! | F45: =Main!#REF! -> #REF! | G45: =Main!#REF! -> #REF!
A46: =Main!#REF! -> #REF! | B46: =Main!#REF! -> #REF! | C46: =Main!#REF! -> #REF! | D46: =Main!#REF! -> #REF! | E46: =Main!#REF! -> #REF! | F46: =Main!#REF! -> #REF! | G46: =Main!#REF! -> #REF!
A47: =Main!A41 -> Какой океан является самым холодным? | B47: =Main!B41 -> Тихий | C47: =Main!C41 -> Атлантический | D47: =Main!D41 -> Индийский | E47: =Main!E41 -> Северный Ледовитый | F47: =Main!F41 -> 4 | G47: =Main!G41 -> Северный Ледовитый океан имеет самые низкие средние температуры воды из-за полярного расположения.
A48: =Main!#REF! -> #REF! | B48: =Main!#REF! -> #REF! | C48: =Main!#REF! -> #REF! | D48: =Main!#REF! -> #REF! | E48: =Main!#REF! -> #REF! | F48: =Main!#REF! -> #REF! | G48: =Main!#REF! -> #REF!
...
